Traceback (most recent call last):
  File "C:\Users\AD\AppData\Local\Programs\Python\Python313\Lib\site-packages\jupyter_core\utils\__init__.py", line 154, in wrapped
    asyncio.get_running_loop()
    ~~~~~~~~~~~~~~~~~~~~~~~~^^
RuntimeError: no running event loop

During handling of the above exception, another exception occurred:

Traceback (most recent call last):
  File "C:\Users\AD\AppData\Local\Programs\Python\Python313\Lib\site-packages\jupyter_cache\executors\utils.py", line 58, in single_nb_execution
    executenb(
    ~~~~~~~~~^
        nb,
        ^^^
    ...<4 lines>...
        **kwargs,
        ^^^^^^^^^
    )
    ^
  File "C:\Users\AD\AppData\Local\Programs\Python\Python313\Lib\site-packages\nbclient\client.py", line 1319, in execute
    return NotebookClient(nb=nb, resources=resources, km=km, **kwargs).execute()
           ~~~~~~~~~~~~~~~~~~~~~~~~~~~~~~~~~~~~~~~~~~~~~~~~~~~~~~~~~~~~~~~~~~~^^
  File "C:\Users\AD\AppData\Local\Programs\Python\Python313\Lib\site-packages\jupyter_core\utils\__init__.py", line 158, in wrapped
    return loop.run_until_complete(inner)
           ~~~~~~~~~~~~~~~~~~~~~~~^^^^^^^
  File "C:\Users\AD\AppData\Local\Programs\Python\Python313\Lib\asyncio\base_events.py", line 725, in run_until_complete
    return future.result()
           ~~~~~~~~~~~~~^^
  File "C:\Users\AD\AppData\Local\Programs\Python\Python313\Lib\site-packages\nbclient\client.py", line 709, in async_execute
    await self.async_execute_cell(
        cell, index, execution_count=self.code_cells_executed + 1
    )
  File "C:\Users\AD\AppData\Local\Programs\Python\Python313\Lib\site-packages\nbclient\client.py", line 1062, in async_execute_cell
    await self._check_raise_for_error(cell, cell_index, exec_reply)
  File "C:\Users\AD\AppData\Local\Programs\Python\Python313\Lib\site-packages\nbclient\client.py", line 918, in _check_raise_for_error
    raise CellExecutionError.from_cell_and_msg(cell, exec_reply_content)
nbclient.exceptions.CellExecutionError: An error occurred while executing the following cell:
------------------
repeat_string({'key_1': 1, 'key_2': 2})
------------------


[31m---------------------------------------------------------------------------[39m
[31mTypeError[39m                                 Traceback (most recent call last)
[36mCell[39m[36m [39m[32mIn[28][39m[32m, line 1[39m
[32m----> [39m[32m1[39m [43mrepeat_string[49m[43m([49m[43m{[49m[33;43m'[39;49m[33;43mkey_1[39;49m[33;43m'[39;49m[43m:[49m[43m [49m[32;43m1[39;49m[43m,[49m[43m [49m[33;43m'[39;49m[33;43mkey_2[39;49m[33;43m'[39;49m[43m:[49m[43m [49m[32;43m2[39;49m[43m}[49m[43m)[49m

[36mCell[39m[36m [39m[32mIn[27][39m[32m, line 24[39m, in [36mrepeat_string[39m[34m(s, times)[39m
[32m     22[39m [38;5;28;01mdef[39;00m[38;5;250m [39m[34mrepeat_string[39m(s: [38;5;28mstr[39m, times: [38;5;28mint[39m = [32m1[39m) -> [38;5;28mstr[39m:
[32m     23[39m [38;5;250m    [39m[33;03m"""Láº·p láº¡i má»™t chuá»—i má»™t sá»‘ láº§n nháº¥t Ä‘á»‹nh."""[39;00m
[32m---> [39m[32m24[39m     [38;5;28;01mreturn[39;00m [43ms[49m[43m [49m[43m*[49m[43m [49m[43mtimes[49m

[31mTypeError[39m: unsupported operand type(s) for *: 'dict' and 'int'

